Workbook

Sheet Setup
A1: Premium Budget System — 2026 (26th–25th Periods)
A3: Income assumptions (net)
A4: FM payday amount (monthly) | B4: 3500
A5: McD payday amount (biweekly) | B5: 400
A6: Outlier payday amount (weekly) | B6: 100
A7: McD next payday date (seed) | B7: 46023
A8: Outlier next payday date (seed - Wed) | B8: 46029
A10: Targets (Aggressive Plan)
A11: Monthly savings transfer target | B11: 1050
A12: Variable cap per period (Food+Donations+Others+One-offs) | B12: 420
A15: Category list (dropdown source)
A16: Group | B16: Category
A17: INCOME | B17: Income - FM
A18: INCOME | B18: Income - McD
A19: INCOME | B19: Income - Outlier
A20: GIVING | B20: Tithe
A21: GIVING | B21: Offerings
A22: GIVING | B22: Charity - Perez Uni
A23: GIVING | B23: Charity - JPC Utilities
A24: GIVING | B24: Donations (Variable)
A25: FIXED | B25: Rent
A26: FIXED | B26: Insurance
A27: FIXED | B27: Road Tax
... A41: POT | B41: Buffer Top-Up
A46: Weekly Pay Yourself
A47: Weekly Allowance (£) | B47: 140
A48: Weeks per Period | B48: 4
A49: Monthly Living Pool (£) | B49: =B47*B48 -> 560
A52: One-Off Giving (Christmas / Special)
A53: Christmas Giving Target (£) | B53: 500
A54: Rule | B54: Fund only from new inflows (Outlier/McD); can be split.

Sheet Mental Allocations
A1: Mental Allocations
A2: This page shows what to mentally set aside when FM arrives. It updates from Setup + Bills Schedule.
A4: Selected Period | B4: =Dashboard!B4 -> 1 | D4: FM received (edit if different) | E4: =Setup!$B$4 -> 3500
A6: Allocation | B6: Amount
A7: Bills + Regular Giving (this period) | B7: =SUM('Bills Schedule'!$C$3:$C$200) -> 4715
A8: Weekly Living Pool (4 weeks) | B8: =Setup!B49 -> 560
A9: Buffer Top-Up (target £800–£1,000) | B9: =0 -> 0
A10: One-Off Giving Pot (Christmas target) | B10: =Setup!B53 -> 500
A11: Savings (sweep near period end) | B11: =0 -> 0
A12: Unassigned / Remaining | B12: =E4-SUM(B7:B11) -> -2275
A13: Notes
A14: • Buffer is NOT for spending. It protects timing gaps.
A15: • One-Off Giving is funded from new inflows (Outlier/McD).
A16: • Savings are a sweep at the end once liquidity is safe.

Sheet Periods 26-25
A1: Period | B1: Label | C1: Start | D1: End | E1: Next Start
A2: 1 | B2: P1: 22 Dec 2025–25 Jan 2026 | C2: 46013 | D2: 46047 | E2: 46048
A3: 2 | B3: P2: 26 Jan 2026–25 Feb 2026 | C3: 46048 | D3: 46078 | E3: 46079
A4: 3 | B4: P3: 26 Feb 2026–25 Mar 2026 | C4: 46079 | D4: 46106 | E4: 46107
A5: 4 | B5: P4: 26 Mar 2026–25 Apr 2026 | C5: 46107 | D5: 46137 | E5: 46138
A6: 5 | B6: P5: 26 Apr 2026–25 May 2026 | C6: 46138 | D6: 46167 | E6: 46168
A7: 6 | B7: P6: 26 May 2026–25 Jun 2026 | C7: 46168 | D7: 46198 | E7: 46199
A8: 7 | B8: P7: 26 Jun 2026–25 Jul 2026 | C8: 46199 | D8: 46228 | E8: 46229
A9: 8 | B9: P8: 26 Jul 2026–25 Aug 2026 | C9: 46229 | D9: 46259 | E9: 46260
A10: 9 | B10: P9: 26 Aug 2026–25 Sep 2026 | C10: 46260 | D10: 46290 | E10: 46291
A11: 10 | B11: P10: 26 Sep 2026–25 Oct 2026 | C11: 46291 | D11: 46320 | E11: 46321
A12: 11 | B12: P11: 26 Oct 2026–25 Nov 2026 | C12: 46321 | D12: 46351 | E12: 46352
A13: 12 | B13: P12: 26 Nov 2026–25 Dec 2026 | C13: 46352 | D13: 46381 | E13: 46382

Sheet Income Schedule
A1: Expected Income Schedule (based on your pay timelines) | G1: InWindow | H1: Key
A2: Date | B2: Source | C2: Expected Amount | D2: Period | E2: Notes
A3: 46013 | B3: FM (Christmas early) | C3: =Setup!$B$4 -> 3500 | D3: =MATCH(A3,'Periods 26-25'!$C$2:$C$13,1) -> 1 | E3: Paid early (Christmas) | G3: =AND($A3>='Upcoming Income'!$B$4,$A3<='Upcoming Income'!$B$4+'Upcoming Income'!$E$4) -> FALSE
A4: 46048 | B4: FM (26th) | C4: =Setup!$B$4 -> 3500 | D4: =MATCH(A3,'Periods 26-25'!$C$2:$C$13,1) -> 1 | E4: Latest by 26th | G4: =AND($A3>='Upcoming Income'!$B$4,$A3<='Upcoming Income'!$B$4+'Upcoming Income'!$E$4) -> FALSE | H4: =IF($G3,$A3+ROW()/100000,"")
A5: 46079 | B5: FM (26th) | C5: =Setup!$B$4 -> 3500 | D5: =MATCH(A4,'Periods 26-25'!$C$2:$C$13,1) -> 2 | E5: Latest by 26th | G5: =AND($A4>='Upcoming Income'!$B$4,$A4<='Upcoming Income'!$B$4+'Upcoming Income'!$E$4) -> TRUE | H5: =IF($G4,$A4+ROW()/100000,"")
A6: 46107 | B6: FM (26th) | C6: =Setup!$B$4 -> 3500 | D6: =MATCH(A5,'Periods 26-25'!$C$2:$C$13,1) -> 3 | E6: Latest by 26th | G6: =AND($A5>='Upcoming Income'!$B$4,$A5<='Upcoming Income'!$B$4+'Upcoming Income'!$E$4) -> FALSE | H6: =IF($G5,$A5+ROW()/100000,"") -> 46079
A7: 46138 | B7: FM (26th) | C7: =Setup!$B$4 -> 3500 | D7: =MATCH(A6,'Periods 26-25'!$C$2:$C$13,1) -> 4 | E7: Latest by 26th | G7: =AND($A6>='Upcoming Income'!$B$4,$A6<='Upcoming Income'!$B$4+'Upcoming Income'!$E$4) -> FALSE | H7: =IF($G6,$A6+ROW()/100000,"")
A8: 46168 | B8: FM (26th) | C8: =Setup!$B$4 -> 3500 | D8: =MATCH(A7,'Periods 26-25'!$C$2:$C$13,1) -> 5 | E8: Latest by 26th | G8: =AND($A7>='Upcoming Income'!$B$4,$A7<='Upcoming Income'!$B$4+'Upcoming Income'!$E$4) -> FALSE | H8: =IF($G7,$A7+ROW()/100000,"")
A9: 46199 | B9: FM (26th) | C9: =Setup!$B$4 -> 3500 | D9: =MATCH(A8,'Periods 26-25'!$C$2:$C$13,1) -> 6 | E9: Latest by 26th | G9: =AND($A8>='Upcoming Income'!$B$4,$A8<='Upcoming Income'!$B$4+'Upcoming Income'!$E$4) -> FALSE | H9: =IF($G8,$A8+ROW()/100000,"")
A10: 46229 | B10: FM (26th) | C10: =Setup!$B$4 -> 3500 | D10: =MATCH(A9,'Periods 26-25'!$C$2:$C$13,1) -> 7 | E10: Latest by 26th | G10: =AND($A9>='Upcoming Income'!$B$4,$A9<='Upcoming Income'!$B$4+'Upcoming Income'!$E$4) -> FALSE | H10: =IF($G9,$A9+ROW()/100000,"")
A11: 46260 | B11: FM (26th) | C11: =Setup!$B$4 -> 3500 | D11: =MATCH(A10,'Periods 26-25'!$C$2:$C$13,1) -> 8 | E11: Latest by 26th | G11: =AND($A10>='Upcoming Income'!$B$4,$A10<='Upcoming Income'!$B$4+'Upcoming Income'!$E$4) -> FALSE | H11: =IF($G10,$A10+ROW()/100000,"")
A12: 46291 | B12: FM (26th) | C12: =Setup!$B$4 -> 3500 | D12: =MATCH(A11,'Periods 26-25'!$C$2:$C$13,1) -> 9 | E12: Latest by 26th | G12: =AND($A11>='Upcoming Income'!$B$4,$A11<='Upcoming Income'!$B$4+'Upcoming Income'!$E$4) -> FALSE | H12: =IF($G11,$A11+ROW()/100000,"")
A13: 46321 | B13: FM (26th) | C13: =Setup!$B$4 -> 3500 | D13: =MATCH(A12,'Periods 26-25'!$C$2:$C$13,1) -> 10 | E13: Latest by 26th | G13: =AND($A12>='Upcoming Income'!$B$4,$A12<='Upcoming Income'!$B$4+'Upcoming Income'!$E$4) -> FALSE | H13: =IF($G12,$A12+ROW()/100000,"")
A14: 46352 | B14: FM (26th) | C14: =Setup!$B$4 -> 3500 | D14: =MATCH(A13,'Periods 26-25'!$C$2:$C$13,1) -> 11 | E14: Latest by 26th | G14: =AND($A13>='Upcoming Income'!$B$4,$A13<='Upcoming Income'!$B$4+'Upcoming Income'!$E$4) -> FALSE | H14: =IF($G13,$A13+ROW()/100000,"")
A15: 46382 | B15: FM (26th) | C15: =Setup!$B$4 -> 3500 | D15: =MATCH(A14,'Periods 26-25'!$C$2:$C$13,1) -> 12 | E15: Latest by 26th | G15: =AND($A14>='Upcoming Income'!$B$4,$A14<='Upcoming Income'!$B$4+'Upcoming Income'!$E$4) -> FALSE | H15: =IF($G14,$A14+ROW()/100000,"")
A16: 46023 | B16: McD (biweekly) | C16: =Setup!$B$5 -> 400 | D16: =MATCH(A15,'Periods 26-25'!$C$2:$C$13,1) -> 12 | E16: Every 2 weeks | G16: =AND($A15>='Upcoming Income'!$B$4,$A15<='Upcoming Income'!$B$4+'Upcoming Income'!$E$4) -> FALSE | H16: =IF($G15,$A15+ROW()/100000,"")
A17: 46037 | B17: McD (biweekly) | C17: =Setup!$B$5 -> 400 | D17: =MATCH(A16,'Periods 26-25'!$C$2:$C$13,1) -> 1 | E17: Every 2 weeks | G17: =AND($A16>='Upcoming Income'!$B$4,$A16<='Upcoming Income'!$B$4+'Upcoming Income'!$E$4) -> TRUE | H17: =IF($G16,$A16+ROW()/100000,"")
A18: 46051 | B18: McD (biweekly) | C18: =Setup!$B$5 -> 400 | D18: =MATCH(A17,'Periods 26-25'!$C$2:$C$13,1) -> 1 | E18: Every 2 weeks | G18: =AND($A17>='Upcoming Income'!$B$4,$A17<='Upcoming Income'!$B$4+'Upcoming Income'!$E$4) -> TRUE | H18: =IF($G17,$A17+ROW()/100000,"") -> 46037
A19: 46065 | B19: McD (biweekly) | C19: =Setup!$B$5 -> 400 | D19: =MATCH(A18,'Periods 26-25'!$C$2:$C$13,1) -> 2 | E19: Every 2 weeks | G19: =AND($A18>='Upcoming Income'!$B$4,$A18<='Upcoming Income'!$B$4+'Upcoming Income'!$E$4) -> FALSE | H19: =IF($G18,$A18+ROW()/100000,"") -> 46051
A20: 46079 | B20: McD (biweekly) | C20: =Setup!$B$5 -> 400 | D20: =MATCH(A19,'Periods 26-25'!$C$2:$C$13,1) -> 2 | E20: Every 2 weeks | G20: =AND($A19>='Upcoming Income'!$B$4,$A19<='Upcoming Income'!$B$4+'Upcoming Income'!$E$4) -> FALSE | H20: =IF($G19,$A19+ROW()/100000,"")
A21: 46093 | B21: McD (biweekly) | C21: =Setup!$B$5 -> 400 | D21: =MATCH(A20,'Periods 26-25'!$C$2:$C$13,1) -> 3 | E21: Every 2 weeks | G21: =AND($A20>='Upcoming Income'!$B$4,$A20<='Upcoming Income'!$B$4+'Upcoming Income'!$E$4) -> FALSE | H21: =IF($G20,$A20+ROW()/100000,"")
A22: 46107 | B22: McD (biweekly) | C22: =Setup!$B$5 -> 400 | D22: =MATCH(A21,'Periods 26-25'!$C$2:$C$13,1) -> 3 | E22: Every 2 weeks | G22: =AND($A21>='Upcoming Income'!$B$4,$A21<='Upcoming Income'!$B$4+'Upcoming Income'!$E$4) -> FALSE | H22: =IF($G21,$A21+ROW()/100000,"")
A23: 46121 | B23: McD (biweekly) | C23: =Setup!$B$5 -> 400 | D23: =MATCH(A22,'Periods 26-25'!$C$2:$C$13,1) -> 4 | E23: Every 2 weeks | G23: =AND($A22>='Upcoming Income'!$B$4,$A22<='Upcoming Income'!$B$4+'Upcoming Income'!$E$4) -> FALSE | H23: =IF($G22,$A22+ROW()/100000,"")
A24: 46135 | B24: McD (biweekly) | C24: =Setup!$B$5 -> 400 | D24: =MATCH(A23,'Periods 26-25'!$C$2:$C$13,1) -> 4 | E24: Every 2 weeks | G24: =AND($A23>='Upcoming Income'!$B$4,$A23<='Upcoming Income'!$B$4+'Upcoming Income'!$E$4) -> FALSE | H24: =IF($G23,$A23+ROW()/100000,"")
A25: 46149 | B25: McD (biweekly) | C25: =Setup!$B$5 -> 400 | D25: =MATCH(A24,'Periods 26-25'!$C$2:$C$13,1) -> 4 | E25: Every 2 weeks | G25: =AND($A24>='Upcoming Income'!$B$4,$A24<='Upcoming Income'!$B$4+'Upcoming Income'!$E$4) -> FALSE | H25: =IF($G24,$A24+ROW()/100000,"")
A26: 46163 | B26: McD (biweekly) | C26: =Setup!$B$5 -> 400 | D26: =MATCH(A25,'Periods 26-25'!$C$2:$C$13,1) -> 5 | E26: Every 2 weeks | G26: =AND($A25>='Upcoming Income'!$B$4,$A25<='Upcoming Income'!$B$4+'Upcoming Income'!$E$4) -> FALSE | H26: =IF($G25,$A25+ROW()/100000,"")
A27: 46177 | B27: McD (biweekly) | C27: =Setup!$B$5 -> 400 | D27: =MATCH(A26,'Periods 26-25'!$C$2:$C$13,1) -> 5 | E27: Every 2 weeks | G27: =AND($A26>='Upcoming Income'!$B$4,$A26<='Upcoming Income'!$B$4+'Upcoming Income'!$E$4) -> FALSE | H27: =IF($G26,$A26+ROW()/100000,"")
... A42: 46387 | B42: McD (biweekly) | C42: =Setup!$B$5 -> 400 | D42: =MATCH(A41,'Periods 26-25'!$C$2:$C$13,1) -> 12 | E42: Every 2 weeks | G42: =AND($A41>='Upcoming Income'!$B$4,$A41<='Upcoming Income'!$B$4+'Upcoming Income'!$E$4) -> FALSE | H42: =IF($G41,$A41+ROW()/100000,"")
A43: 46029 | B43: Outlier (weekly Wed) | C43: =Setup!$B$6 -> 100 | D43: =MATCH(A42,'Periods 26-25'!$C$2:$C$13,1) -> 12 | E43: Weekly Wednesday | G43: =AND($A42>='Upcoming Income'!$B$4,$A42<='Upcoming Income'!$B$4+'Upcoming Income'!$E$4) -> FALSE | H43: =IF($G42,$A42+ROW()/100000,"")
A44: 46036 | B44: Outlier (weekly Wed) | C44: =Setup!$B$6 -> 100 | D44: =MATCH(A43,'Periods 26-25'!$C$2:$C$13,1) -> 1 | E44: Weekly Wednesday | G44: =AND($A43>='Upcoming Income'!$B$4,$A43<='Upcoming Income'!$B$4+'Upcoming Income'!$E$4) -> TRUE | H44: =IF($G43,$A43+ROW()/100000,"")
A45: 46043 | B45: Outlier (weekly Wed) | C45: =Setup!$B$6 -> 100 | D45: =MATCH(A44,'Periods 26-25'!$C$2:$C$13,1) -> 1 | E45: Weekly Wednesday | G45: =AND($A44>='Upcoming Income'!$B$4,$A44<='Upcoming Income'!$B$4+'Upcoming Income'!$E$4) -> TRUE | H45: =IF($G44,$A44+ROW()/100000,"") -> 46036
A46: 46050 | B46: Outlier (weekly Wed) | C46: =Setup!$B$6 -> 100 | D46: =MATCH(A45,'Periods 26-25'!$C$2:$C$13,1) -> 1 | E46: Weekly Wednesday | G46: =AND($A45>='Upcoming Income'!$B$4,$A45<='Upcoming Income'!$B$4+'Upcoming Income'!$E$4) -> TRUE | H46: =IF($G45,$A45+ROW()/100000,"") -> 46043
A47: 46057 | B47: Outlier (weekly Wed) | C47: =Setup!$B$6 -> 100 | D47: =MATCH(A46,'Periods 26-25'!$C$2:$C$13,1) -> 2 | E47: Weekly Wednesday | G47: =AND($A46>='Upcoming Income'!$B$4,$A46<='Upcoming Income'!$B$4+'Upcoming Income'!$E$4) -> TRUE | H47: =IF($G46,$A46+ROW()/100000,"") -> 46050
A48: 46064 | B48: Outlier (weekly Wed) | C48: =Setup!$B$6 -> 100 | D48: =MATCH(A47,'Periods 26-25'!$C$2:$C$13,1) -> 2 | E48: Weekly Wednesday | G48: =AND($A47>='Upcoming Income'!$B$4,$A47<='Upcoming Income'!$B$4+'Upcoming Income'!$E$4) -> FALSE | H48: =IF($G47,$A47+ROW()/100000,"") -> 46057
A49: 46071 | B49: Outlier (weekly Wed) | C49: =Setup!$B$6 -> 100 | D49: =MATCH(A48,'Periods 26-25'!$C$2:$C$13,1) -> 2 | E49: Weekly Wednesday | G49: =AND($A48>='Upcoming Income'!$B$4,$A48<='Upcoming Income'!$B$4+'Upcoming Income'!$E$4) -> FALSE | H49: =IF($G48,$A48+ROW()/100000,"")
A50: 46078 | B50: Outlier (weekly Wed) | C50: =Setup!$B$6 -> 100 | D50: =MATCH(A49,'Periods 26-25'!$C$2:$C$13,1) -> 2 | E50: Weekly Wednesday | G50: =AND($A49>='Upcoming Income'!$B$4,$A49<='Upcoming Income'!$B$4+'Upcoming Income'!$E$4) -> FALSE | H50: =IF($G49,$A49+ROW()/100000,"")
A51: 46085 | B51: Outlier (weekly Wed) | C51: =Setup!$B$6 -> 100 | D51: =MATCH(A50,'Periods 26-25'!$C$2:$C$13,1) -> 2 | E51: Weekly Wednesday | G51: =AND($A50>='Upcoming Income'!$B$4,$A50<='Upcoming Income'!$B$4+'Upcoming Income'!$E$4) -> FALSE | H51: =IF($G50,$A50+ROW()/100000,"")
A52: 46092 | B52: Outlier (weekly Wed) | C52: =Setup!$B$6 -> 100 | D52: =MATCH(A51,'Periods 26-25'!$C$2:$C$13,1) -> 3 | E52: Weekly Wednesday | G52: =AND($A51>='Upcoming Income'!$B$4,$A51<='Upcoming Income'!$B$4+'Upcoming Income'!$E$4) -> FALSE | H52: =IF($G51,$A51+ROW()/100000,"")
A53: 46099 | B53: Outlier (weekly Wed) | C53: =Setup!$B$6 -> 100 | D53: =MATCH(A52,'Periods 26-25'!$C$2:$C$13,1) -> 3 | E53: Weekly Wednesday | G53: =AND($A52>='Upcoming Income'!$B$4,$A52<='Upcoming Income'!$B$4+'Upcoming Income'!$E$4) -> FALSE | H53: =IF($G52,$A52+ROW()/100000,"")
A54: 46106 | B54: Outlier (weekly Wed) | C54: =Setup!$B$6 -> 100 | D54: =MATCH(A53,'Periods 26-25'!$C$2:$C$13,1) -> 3 | E54: Weekly Wednesday | G54: =AND($A53>='Upcoming Income'!$B$4,$A53<='Upcoming Income'!$B$4+'Upcoming Income'!$E$4) -> FALSE | H54: =IF($G53,$A53+ROW()/100000,"")
...

Sheet Transactions
A1: Date | B1: Type | C1: Category | D1: Description | E1: Amount (£) | F1: One-off? | G1: Payment Method | H1: Notes | I1: Period (auto)
A2: 46006 | B2: Expense | C2: Others | D2: Apple cloud subscription | E2: 2.99 | F2: No | G2: Direct Debit | H2: Cloud storage | I2: =IFERROR(MATCH(A2,'Periods 26-25'!$C$2:$C$13,1),"")
A3: 46007 | B3: Expense | C3: Electricity & Gas | D3: Electricity | E3: 10 | F3: No | G3: Apple Pay | H3: Electricity | I3: =IFERROR(MATCH(A3,'Periods 26-25'!$C$2:$C$13,1),"")
A4: 46008 | B4: Expense | C4: Electricity & Gas | D4: Electricity | E4: 10 | F4: No | G4: Apple Pay | H4: Gas | I4: =IFERROR(MATCH(A4,'Periods 26-25'!$C$2:$C$13,1),"")
A5: 46008 | B5: Expense | C5: Food | D5: Costco | E5: 45.6 | F5: No | G5: Apple Pay | H5: Food for the house | I5: =IFERROR(MATCH(A5,'Periods 26-25'!$C$2:$C$13,1),"")
A6: 46009 | B6: Expense | C6: Food | D6: Tesco | E6: 4.99 | F6: No | G6: Apple Pay | H6: water for the house | I6: =IFERROR(MATCH(A6,'Periods 26-25'!$C$2:$C$13,1),"")
A7: 46010 | B7: Expense | C7: Food | D7: Costco | E7: 4 | F7: No | G7: Apple Pay | H7: egg | I7: =IFERROR(MATCH(A7,'Periods 26-25'!$C$2:$C$13,1),"")
A8: 46007 | B8: Expense | C8: Others | D8: Transportation - TfL | E8: 7.2 | F8: No | G8: Apple Pay | H8: To the office | I8: =IFERROR(MATCH(A8,'Periods 26-25'!$C$2:$C$13,1),"")
A9: 46010 | B9: Expense | C9: Others | D9: Fuel | E9: 30.01 | F9: No | G9: Apple Pay | H9: for the week | I9: =IFERROR(MATCH(A9,'Periods 26-25'!$C$2:$C$13,1),"")
A10: 46011 | B10: Expense | C10: Others | D10: Transportation - TfL | E10: 10.1 | F10: No | G10: Apple Pay | H10: To Milton keynes - train disruption | I10: =IFERROR(MATCH(A10,'Periods 26-25'!$C$2:$C$13,1),"")
A11: 46011 | B11: Expense | C11: Others | D11: Transportation - TfL | E11: 4.97 | F11: No | G11: Apple Pay | H11: Uber to PKG address | I11: =IFERROR(MATCH(A11,'Periods 26-25'!$C$2:$C$13,1),"")
A12: 46012 | B12: Expense | C12: Others | D12: Tyre puncture | E12: 10 | F12: Yes | G12: Apple Pay | H12: flat tyre, puncture repaired | I12: =IFERROR(MATCH(A12,'Periods 26-25'!$C$2:$C$13,1),"")
A13: 46013 | B13: Income | C13: Income - FM | D13: December Salary | E13: 3700 | F13: No | G13: Bank transfer | H13: N/A | I13: =IFERROR(MATCH(A13,'Periods 26-25'!$C$2:$C$13,1),"") -> 1
... A20: 46014 | B20: Expense | C20: Offerings | D20: Thanksgiving Offering | E20: 60 | F20: No | G20: Bank transfer | H20: Offering for December - PJ | I20: =IFERROR(MATCH(A20,'Periods 26-25'!$C$2:$C$13,1),"") -> 1
A21: 46014 | B21: Expense | C21: Parents | D21: Mummy J and Mummy R | E21: =65+75 -> 140 | F21: No | G21: Bank transfer | H21: Allowance for December | I21: =IFERROR(MATCH(A21,'Periods 26-25'!$C$2:$C$13,1),"") -> 1
A22: 46015 | B22: Income | C22: Income - Outlier | D22: Outlier on 24/12/2025 | E22: 111.48 | F22: No | G22: Bank transfer | H22: Weekly allowance | I22: =IFERROR(MATCH(A22,'Periods 26-25'!$C$2:$C$13,1),"") -> 1
A23: 46015 | B23: Expense | C23: Tithe | D23: Outlier Tithe | E23: 12 | F23: No | G23: Bank transfer | H23: Tithe on Outlier | I23: =IFERROR(MATCH(A23,'Periods 26-25'!$C$2:$C$13,1),"") -> 1
A24: 46014 | B24: Expense | C24: House Keep | D24: Wipes | E24: 11.25 | F24: No | G24: Apple Pay | H24: wipes for Josh | I24: =IFERROR(MATCH(A24,'Periods 26-25'!$C$2:$C$13,1),"") -> 1
A25: 46013 | B25: Expense | C25: Credit Card Payment | D25: Monzo payment | E25: 295.21 | F25: No | G25: Apple Pay | H25: Monzo payment - Dec | I25: =IFERROR(MATCH(A25,'Periods 26-25'!$C$2:$C$13,1),"") -> 1
A26: 46013 | B26: Expense | C26: Charity - Perez Uni | D26: Sacrifice for Dec | E26: 50 | F26: No | G26: Bank transfer | H26: December contribution | I26: =IFERROR(MATCH(A26,'Periods 26-25'!$C$2:$C$13,1),"") -> 1
A27: 46013 | B27: Expense | C27: House Keep | D27: Lebara | E27: 9 | F27: No | G27: Apple Pay | H27: Data wifey | I27: =IFERROR(MATCH(A27,'Periods 26-25'!$C$2:$C$13,1),"") -> 1
A28: 46013 | B28: Expense | C28: House Keep | D28: Body wash | E28: 16.5 | F28: No | G28: Apple Pay | H28: Avon comestics | I28: =IFERROR(MATCH(A28,'Periods 26-25'!$C$2:$C$13,1),"") -> 1
A29: 46015 | B29: Expense | C29: One-Off Giving (Christmas) | D29: Gift to families | E29: 457.37 | F29: Yes | G29: Bank transfer | H29: Gift for the Christmas Season | I29: =IFERROR(MATCH(A29,'Periods 26-25'!$C$2:$C$13,1),"") -> 1
A30: 46015 | B30: Expense | C30: Electricity & Gas | D30: Electricity | E30: 10 | F30: No | G30: Apple Pay | H30: Electricity for the house | I30: =IFERROR(MATCH(A30,'Periods 26-25'!$C$2:$C$13,1),"") -> 1
A31: 46015 | B31: Expense | C31: House Keep | D31: Ingredients for cake | E31: 7.78 | F31: No | G31: Apple Pay | H31: Cake for Auntie Faith & Fam | I31: =IFERROR(MATCH(A31,'Periods 26-25'!$C$2:$C$13,1),"") -> 1
A32: 46015 | B32: Expense | C32: Fuel | D32: Fuel for Renault Scenic | E32: 30.17 | F32: No | G32: Apple Pay | H32: on the 24/12 - Fuel | I32: =IFERROR(MATCH(A32,'Periods 26-25'!$C$2:$C$13,1),"") -> 1
A33: 46017 | B33: Expense | C33: iPhone Payments | D33: payment for wifey's phone | E33: 29 | F33: No | G33: Bank transfer | H33: last payment for iphone 13 | I33: =IFERROR(MATCH(A33,'Periods 26-25'!$C$2:$C$13,1),"") -> 1
... A47: 46020 | B47: Expense | C47: Electricity & Gas | D47: Gas | E47: 10 | F47: No | G47: Apple Pay | H47: Gas for the house | I47: =IFERROR(MATCH(A47,'Periods 26-25'!$C$2:$C$13,1),"") -> 1
I48: =IFERROR(MATCH(A48,'Periods 26-25'!$C$2:$C$13,1),"")
I49: =IFERROR(MATCH(A49,'Periods 26-25'!$C$2:$C$13,1),"")
I50: =IFERROR(MATCH(A50,'Periods 26-25'!$C$2:$C$13,1),"")
I51: =IFERROR(MATCH(A51,'Periods 26-25'!$C$2:$C$13,1),"")
I52: =IFERROR(MATCH(A52,'Periods 26-25'!$C$2:$C$13,1),"")
I53: =IFERROR(MATCH(A53,'Periods 26-25'!$C$2:$C$13,1),"")
I54: =IFERROR(MATCH(A54,'Periods 26-25'!$C$2:$C$13,1),"")
I55: =IFERROR(MATCH(A55,'Periods 26-25'!$C$2:$C$13,1),"")
I56: =IFERROR(MATCH(A56,'Periods 26-25'!$C$2:$C$13,1),"")
I57: =IFERROR(MATCH(A57,'Periods 26-25'!$C$2:$C$13,1),"")
I58: =IFERROR(MATCH(A58,'Periods 26-25'!$C$2:$C$13,1),"")
I59: =IFERROR(MATCH(A59,'Periods 26-25'!$C$2:$C$13,1),"")
...

Sheet Bills Schedule
A1: Bills & Fixed Expenses Schedule (typically 26th–3rd)
A2: Bill | B2: Typical Due Day | C2: Budget / Period | D2: Paid? (tick) | E2: Period | F2: Actual Paid (auto) | G2: Variance | H2: Notes | O2: Monthly contribution
A3: Rent | B3: 28 | C3: 550 | E3: 1 | F3: =IF($E3="","",SUMIFS(Transactions!$E:$E,Transactions!$C:$C,$A3,Transactions!$B:$B,"Expense",Transactions!$I:$I,$E3)) -> 0 | G3: =F3-C3 -> -550 | K3: * To add transfers for prudential | O3: GhS | P3: £ | Q3: £
A4: Insurance | B4: 28 | C4: 175 | E4: 1 | F4: =IF($E4="","",SUMIFS(Transactions!$E:$E,Transactions!$C:$C,$A4,Transactions!$B:$B,"Expense",Transactions!$I:$I,$E4)) -> 0 | G4: =F4-C4 -> -175 | K4: - GhS 100k for children Education | O4: 516.63 | P4: =O4/15 -> 34.442 | Q4: 35 | R4: from April
A5: Road Tax | B5: 28 | C5: 34 | E5: 1 | F5: =IF($E5="","",SUMIFS(Transactions!$E:$E,Transactions!$C:$C,$A5,Transactions!$B:$B,"Expense",Transactions!$I:$I,$E5)) -> 0 | G5: =F5-C5 -> -34 | K5: - GhS 100K for Bishop at 60years | O5: 1346.83 | P5: =O5/15 -> 89.788667 | Q5: 90 | R5: from Dec
A6: Water Bill | B6: 28 | C6: 93 | E6: 1 | F6: =IF($E6="","",SUMIFS(Transactions!$E:$E,Transactions!$C:$C,$A6,Transactions!$B:$B,"Expense",Transactions!$I:$I,$E6)) -> 92.77 | G6: =F6-C6 -> -0.23 | K6: - GhS 12K for student loan | O6: 500 | P6: =O6/15 -> 33.333333 | Q6: 34 | R6: from Dec
A7: Community Fibre / Internet | B7: 26 | C7: 37 | E7: 1 | F7: =IF($E7="","",SUMIFS(Transactions!$E:$E,Transactions!$C:$C,$A7,Transactions!$B:$B,"Expense",Transactions!$I:$I,$E7)) -> 36.83 | G7: =F7-C7 -> -0.17 | K7: - GhS 50K for Mr Mensah | O7: 187.3 | P7: =O7/15 -> 12.486667 | Q7: 13 | R7: from Dec
A8: Electricity & Gas | B8: 26 | C8: 200 | E8: 1 | F8: =IF($E8="","",SUMIFS(Transactions!$E:$E,Transactions!$C:$C,$A8,Transactions!$B:$B,"Expense",Transactions!$I:$I,$E8)) -> 50 | G8: =F8-C8 -> -150 | O8: =SUM(O4:O7) -> 2550.76 | P8: =SUM(P4:P7) -> 170.05067 | Q8: =SUM(Q4:Q7) -> 172
A9: iPhone Payments | B9: 26 | C9: 108 | E9: 1 | F9: =IF($E9="","",SUMIFS(Transactions!$E:$E,Transactions!$C:$C,$A9,Transactions!$B:$B,"Expense",Transactions!$I:$I,$E9)) -> 53.95 | G9: =F9-C9 -> -54.05
A10: Parents | B10: 26 | C10: 140 | E10: 1 | F10: =IF($E10="","",SUMIFS(Transactions!$E:$E,Transactions!$C:$C,$A10,Transactions!$B:$B,"Expense",Transactions!$I:$I,$E10)) -> 140 | G10: =F10-C10 -> 0
A11: Credit Card Payment | B11: 26 | C11: 400 | E11: 1 | F11: =IF($E11="","",SUMIFS(Transactions!$E:$E,Transactions!$C:$C,$A11,Transactions!$B:$B,"Expense",Transactions!$I:$I,$E11)) -> 438.92 | G11: =F11-C11 -> 38.92 | Q11: 3500
A12: Fuel | B12: 26 | C12: 100 | E12: 1 | F12: =IF($E12="","",SUMIFS(Transactions!$E:$E,Transactions!$C:$C,$A12,Transactions!$B:$B,"Expense",Transactions!$I:$I,$E12)) -> 30.17 | G12: =F12-C12 -> -69.83 | Q12: 800
A13: Tithe | B13: 26 | C13: 410 | E13: 1 | F13: =IF($E13="","",SUMIFS(Transactions!$E:$E,Transactions!$C:$C,$A13,Transactions!$B:$B,"Expense",Transactions!$I:$I,$E13)) -> 383 | G13: =F13-C13 -> -27 | Q13: 400 | S13: =SUM(Q11:Q13) -> 4700
A14: Offerings | B14: 26 | C14: 165 | E14: 1 | F14: =IF($E14="","",SUMIFS(Transactions!$E:$E,Transactions!$C:$C,$A14,Transactions!$B:$B,"Expense",Transactions!$I:$I,$E14)) -> 140 | G14: =F14-C14 -> -25 | Q14: 3165 | S14: =S13-Q14 -> 1535 | T14: =S14/S13 -> 0.32659574
A15: Charity - Perez Uni | B15: 26 | C15: 50 | E15: 1 | F15: =IF($E15="","",SUMIFS(Transactions!$E:$E,Transactions!$C:$C,$A15,Transactions!$B:$B,"Expense",Transactions!$I:$I,$E15)) -> 50 | G15: =F15-C15 -> 0 | J15: 3163
A16: Charity - JPC Utilities | B16: 26 | C16: 100 | E16: 1 | F16: =IF($E16="","",SUMIFS(Transactions!$E:$E,Transactions!$C:$C,$A16,Transactions!$B:$B,"Expense",Transactions!$I:$I,$E16)) -> 100 | G16: =F16-C16 -> 0 | I16: 1104.62 | J16: 457.37 | K16: 130.68 | L16: =J16-K16 -> 326.69 | S16: 1050 | T16: =S16/S13 -> 0.22340426
A17: Savings Transfer | B17: 29 | C17: 1050 | E17: 1 | F17: =IF($E17="","",SUMIFS(Transactions!$E:$E,Transactions!$C:$C,$A17,Transactions!$B:$B,"Transfer",Transactions!$I:$I,$E17)) -> 0 | G17: =F17-C17 -> -1050 | J17: =SUM(J15:J16) -> 3620.37
A18: Laptop | B18: 29 | C18: 43 | E18: 1 | F18: =IF($E18="","",SUMIFS(Transactions!$E:$E,Transactions!$C:$C,$A18,Transactions!$B:$B,"Expense",Transactions!$I:$I,$E18)) -> 43 | G18: =F18-C18 -> 0 | J18: 3708 | S18: =S14-S16 -> 485
A19: House Keep | B19: 26 | C19: 560 | E19: 1 | F19: =IF($E19="","",SUMIFS(Transactions!$E:$E,Transactions!$C:$C,$A19,Transactions!$B:$B,"Expense",Transactions!$I:$I,$E19)) -> 129.97 | G19: =F19-C19 -> -430.03 | J19: =J18-J17 -> 87.63
A20: One-Off Giving (Christmas) | B20: 26 | C20: 500 | E20: 1 | F20: =IF($E20="","",SUMIFS(Transactions!$E:$E,Transactions!$C:$C,$A20,Transactions!$B:$B,"Expense",Transactions!$I:$I,$E20)) -> 457.37 | G20: =F20-C20 -> -42.63 | H20: One-Off
I21: =I16-J16+99 -> 746.25
I22: 550
I23: 111.62
I24: 32.09
I25: 25
A27: 735.39 | C27: Halifax | I27: =I21-SUM(I22:I25) -> 27.54
A28: =22.41+320 -> 342.41 | C28: Monzo
A29: =173.67+350.15+300+25.06 -> 848.88 | C29: Revolut
A30: 140

Sheet Budget by Period
A1: Budget vs Actual by Period (26th–25th) — auto from Transactions | B1: Items | D1: Budget | E1: Actuals | F1: Variance | G1: Budget | H1: Actuals | I1: Variance | J1: Budget | K1: Actuals | L1: Variance | M1: Budget | N1: Actuals | O1: Variance | P1: Budget | Q1: Actuals | R1: Variance | S1: Budget | T1: Actuals | U1: Variance | V1: Budget | W1: Actuals | X1: Variance | Y1: Budget | Z1: Actuals | AA1: Variance | AB1: Budget | AC1: Actuals | AD1: Variance | AE1: Budget | AF1: Actuals | AG1: Variance | AH1: Budget | AI1: Actuals | AJ1: Variance | AK1: Budget | AL1: Actuals | AM1: Variance
A2: INCOME | B2: Income - FM | C2: 3500 | D2: =$C2 -> 3500 | E2: =SUMIFS(Transactions!$E:$E,Transactions!$C:$C,$B2,Transactions!$B:$B,"Income",Transactions!$I:$I,1) -> 3700 | F2: =E2-D2 -> 200 | G2: =$C2 -> 3500 | H2: =SUMIFS(Transactions!$E:$E,Transactions!$C:$C,$B2,Transactions!$B:$B,"Income",Transactions!$I:$I,2) -> 0 | I2: =H2-G2 -> -3500 | J2: =$C2 -> 3500 | K2: =SUMIFS(Transactions!$E:$E,Transactions!$C:$C,$B2,Transactions!$B:$B,"Income",Transactions!$I:$I,3) -> 0 | L2: =K2-J2 -> -3500 | M2: =$C2 -> 3500 | N2: =SUMIFS(Transactions!$E:$E,Transactions!$C:$C,$B2,Transactions!$B:$B,"Income",Transactions!$I:$I,4) -> 0 | O2: =N2-M2 -> -3500 | P2: =$C2 -> 3500 | Q2: =SUMIFS(Transactions!$E:$E,Transactions!$C:$C,$B2,Transactions!$B:$B,"Income",Transactions!$I:$I,5) -> 0 | R2: =Q2-P2 -> -3500 | S2: =$C2 -> 3500 | T2: =SUMIFS(Transactions!$E:$E,Transactions!$C:$C,$B2,Transactions!$B:$B,"Income",Transactions!$I:$I,6) -> 0 | U2: =T2-S2 -> -3500 | V2: =$C2 -> 3500 | W2: =SUMIFS(Transactions!$E:$E,Transactions!$C:$C,$B2,Transactions!$B:$B,"Income",Transactions!$I:$I,7) -> 0 | X2: =W2-V2 -> -3500 | Y2: =$C2 -> 3500 | Z2: =SUMIFS(Transactions!$E:$E,Transactions!$C:$C,$B2,Transactions!$B:$B,"Income",Transactions!$I:$I,8) -> 0 | AA2: =Z2-Y2 -> -3500 | AB2: =$C2 -> 3500 | AC2: =SUMIFS(Transactions!$E:$E,Transactions!$C:$C,$B2,Transactions!$B:$B,"Income",Transactions!$I:$I,9) -> 0 | AD2: =AC2-AB2 -> -3500 | AE2: =$C2 -> 3500 | AF2: =SUMIFS(Transactions!$E:$E,Transactions!$C:$C,$B2,Transactions!$B:$B,"Income",Transactions!$I:$I,10) -> 0 | AG2: =AF2-AE2 -> -3500 | AH2: =$C2 -> 3500 | AI2: =SUMIFS(Transactions!$E:$E,Transactions!$C:$C,$B2,Transactions!$B:$B,"Income",Transactions!$I:$I,11) -> 0 | AJ2: =AI2-AH2 -> -3500 | AK2: =$C2 -> 3500 | AL2: =SUMIFS(Transactions!$E:$E,Transactions!$C:$C,$B2,Transactions!$B:$B,"Income",Transactions!$I:$I,12) -> 0 | AM2: =AL2-AK2 -> -3500
A3: INCOME | B3: Income - McD | C3: 800 | D3: =$C3 -> 800 | E3: =SUMIFS(Transactions!$E:$E,Transactions!$C:$C,$B3,Transactions!$B:$B,"Income",Transactions!$I:$I,1) -> 0 | F3: =E3-D3 -> -800 | G3: =$C3 -> 800 | H3: =SUMIFS(Transactions!$E:$E,Transactions!$C:$C,$B3,Transactions!$B:$B,"Income",Transactions!$I:$I,2) -> 0 | I3: =H3-G3 -> -800 | J3: =$C3 -> 800 | K3: =SUMIFS(Transactions!$E:$E,Transactions!$C:$C,$B3,Transactions!$B:$B,"Income",Transactions!$I:$I,3) -> 0 | L3: =K3-J3 -> -800 | M3: =$C3 -> 800 | N3: =SUMIFS(Transactions!$E:$E,Transactions!$C:$C,$B3,Transactions!$B:$B,"Income",Transactions!$I:$I,4) -> 0 | O3: =N3-M3 -> -800 | P3: =$C3 -> 800 | Q3: =SUMIFS(Transactions!$E:$E,Transactions!$C:$C,$B3,Transactions!$B:$B,"Income",Transactions!$I:$I,5) -> 0 | R3: =Q3-P3 -> -800 | S3: =$C3 -> 800 | T3: =SUMIFS(Transactions!$E:$E,Transactions!$C:$C,$B3,Transactions!$B:$B,"Income",Transactions!$I:$I,6) -> 0 | U3: =T3-S3 -> -800 | V3: =$C3 -> 800 | W3: =SUMIFS(Transactions!$E:$E,Transactions!$C:$C,$B3,Transactions!$B:$B,"Income",Transactions!$I:$I,7) -> 0 | X3: =W3-V3 -> -800 | Y3: =$C3 -> 800 | Z3: =SUMIFS(Transactions!$E:$E,Transactions!$C:$C,$B3,Transactions!$B:$B,"Income",Transactions!$I:$I,8) -> 0 | AA3: =Z3-Y3 -> -800 | AB3: =$C3 -> 800 | AC3: =SUMIFS(Transactions!$E:$E,Transactions!$C:$C,$B3,Transactions!$B:$B,"Income",Transactions!$I:$I,9) -> 0 | AD3: =AC3-AB3 -> -800 | AE3: =$C3 -> 800 | AF3: =SUMIFS(Transactions!$E:$E,Transactions!$C:$C,$B3,Transactions!$B:$B,"Income",Transactions!$I:$I,10) -> 0 | AG3: =AF3-AE3 -> -800 | AH3: =$C3 -> 800 | AI3: =SUMIFS(Transactions!$E:$E,Transactions!$C:$C,$B3,Transactions!$B:$B,"Income",Transactions!$I:$I,11) -> 0 | AJ3: =AI3-AH3 -> -800 | AK3: =$C3 -> 800 | AL3: =SUMIFS(Transactions!$E:$E,Transactions!$C:$C,$B3,Transactions!$B:$B,"Income",Transactions!$I:$I,12) -> 0 | AM3: =AL3-AK3 -> -800
A4: INCOME | B4: Income - Outlier | C4: 400 | D4: =$C4 -> 400 | E4: =SUMIFS(Transactions!$E:$E,Transactions!$C:$C,$B4,Transactions!$B:$B,"Income",Transactions!$I:$I,1) -> 111.48 | F4: =E4-D4 -> -288.52 | G4: =$C4 -> 400 | H4: =SUMIFS(Transactions!$E:$E,Transactions!$C:$C,$B4,Transactions!$B:$B,"Income",Transactions!$I:$I,2) -> 0 | I4: =H4-G4 -> -400 | J4: =$C4 -> 400 | K4: =SUMIFS(Transactions!$E:$E,Transactions!$C:$C,$B4,Transactions!$B:$B,"Income",Transactions!$I:$I,3) -> 0 | L4: =K4-J4 -> -400 | M4: =$C4 -> 400 | N4: =SUMIFS(Transactions!$E:$E,Transactions!$C:$C,$B4,Transactions!$B:$B,"Income",Transactions!$I:$I,4) -> 0 | O4: =N4-M4 -> -400 | P4: =$C4 -> 400 | Q4: =SUMIFS(Transactions!$E:$E,Transactions!$C:$C,$B4,Transactions!$B:$B,"Income",Transactions!$I:$I,5) -> 0 | R4: =Q4-P4 -> -400 | S4: =$C4 -> 400 | T4: =SUMIFS(Transactions!$E:$E,Transactions!$C:$C,$B4,Transactions!$B:$B,"Income",Transactions!$I:$I,6) -> 0 | U4: =T4-S4 -> -400 | V4: =$C4 -> 400 | W4: =SUMIFS(Transactions!$E:$E,Transactions!$C:$C,$B4,Transactions!$B:$B,"Income",Transactions!$I:$I,7) -> 0 | X4: =W4-V4 -> -400 | Y4: =$C4 -> 400 | Z4: =SUMIFS(Transactions!$E:$E,Transactions!$C:$C,$B4,Transactions!$B:$B,"Income",Transactions!$I:$I,8) -> 0 | AA4: =Z4-Y4 -> -400 | AB4: =$C4 -> 400 | AC4: =SUMIFS(Transactions!$E:$E,Transactions!$C:$C,$B4,Transactions!$B:$B,"Income",Transactions!$I:$I,9) -> 0 | AD4: =AC4-AB4 -> -400 | AE4: =$C4 -> 400 | AF4: =SUMIFS(Transactions!$E:$E,Transactions!$C:$C,$B4,Transactions!$B:$B,"Income",Transactions!$I:$I,10) -> 0 | AG4: =AF4-AE4 -> -400 | AH4: =$C4 -> 400 | AI4: =SUMIFS(Transactions!$E:$E,Transactions!$C:$C,$B4,Transactions!$B:$B,"Income",Transactions!$I:$I,11) -> 0 | AJ4: =AI4-AH4 -> -400 | AK4: =$C4 -> 400 | AL4: =SUMIFS(Transactions!$E:$E,Transactions!$C:$C,$B4,Transactions!$B:$B,"Income",Transactions!$I:$I,12) -> 0 | AM4: =AL4-AK4 -> -400
A5: GIVING | B5: Tithe | C5: 410 | D5: =$C5 -> 410 | E5: =SUMIFS(Transactions!$E:$E,Transactions!$C:$C,$B5,Transactions!$B:$B,"Expense",Transactions!$I:$I,1) -> 383 | F5: =E5-D5 -> -27 | G5: =$C5 -> 410 | H5: =SUMIFS(Transactions!$E:$E,Transactions!$C:$C,$B5,Transactions!$B:$B,"Expense",Transactions!$I:$I,2) -> 0 | I5: =H5-G5 -> -410 | J5: =$C5 -> 410 | K5: =SUMIFS(Transactions!$E:$E,Transactions!$C:$C,$B5,Transactions!$B:$B,"Expense",Transactions!$I:$I,3) -> 0 | L5: =K5-J5 -> -410 | M5: =$C5 -> 410 | N5: =SUMIFS(Transactions!$E:$E,Transactions!$C:$C,$B5,Transactions!$B:$B,"Expense",Transactions!$I:$I,4) -> 0 | O5: =N5-M5 -> -410 | P5: =$C5 -> 410 | Q5: =SUMIFS(Transactions!$E:$E,Transactions!$C:$C,$B5,Transactions!$B:$B,"Expense",Transactions!$I:$I,5) -> 0 | R5: =Q5-P5 -> -410 | S5: =$C5 -> 410 | T5: =SUMIFS(Transactions!$E:$E,Transactions!$C:$C,$B5,Transactions!$B:$B,"Expense",Transactions!$I:$I,6) -> 0 | U5: =T5-S5 -> -410 | V5: =$C5 -> 410 | W5: =SUMIFS(Transactions!$E:$E,Transactions!$C:$C,$B5,Transactions!$B:$B,"Expense",Transactions!$I:$I,7) -> 0 | X5: =W5-V5 -> -410 | Y5: =$C5 -> 410 | Z5: =SUMIFS(Transactions!$E:$E,Transactions!$C:$C,$B5,Transactions!$B:$B,"Expense",Transactions!$I:$I,8) -> 0 | AA5: =Z5-Y5 -> -410 | AB5: =$C5 -> 410 | AC5: =SUMIFS(Transactions!$E:$E,Transactions!$C:$C,$B5,Transactions!$B:$B,"Expense",Transactions!$I:$I,9) -> 0 | AD5: =AC5-AB5 -> -410 | AE5: =$C5 -> 410 | AF5: =SUMIFS(Transactions!$E:$E,Transactions!$C:$C,$B5,Transactions!$B:$B,"Expense",Transactions!$I:$I,10) -> 0 | AG5: =AF5-AE5 -> -410 | AH5: =$C5 -> 410 | AI5: =SUMIFS(Transactions!$E:$E,Transactions!$C:$C,$B5,Transactions!$B:$B,"Expense",Transactions!$I:$I,11) -> 0 | AJ5: =AI5-AH5 -> -410 | AK5: =$C5 -> 410 | AL5: =SUMIFS(Transactions!$E:$E,Transactions!$C:$C,$B5,Transactions!$B:$B,"Expense",Transactions!$I:$I,12) -> 0 | AM5: =AL5-AK5 -> -410
A6: GIVING | B6: Offerings | C6: 165 | D6: =$C6 -> 165 | E6: =SUMIFS(Transactions!$E:$E,Transactions!$C:$C,$B6,Transactions!$B:$B,"Expense",Transactions!$I:$I,1) -> 140 | F6: =E6-D6 -> -25 | G6: =$C6 -> 165 | H6: =SUMIFS(Transactions!$E:$E,Transactions!$C:$C,$B6,Transactions!$B:$B,"Expense",Transactions!$I:$I,2) -> 0 | I6: =H6-G6 -> -165 | J6: =$C6 -> 165 | K6: =SUMIFS(Transactions!$E:$E,Transactions!$C:$C,$B6,Transactions!$B:$B,"Expense",Transactions!$I:$I,3) -> 0 | L6: =K6-J6 -> -165 | M6: =$C6 -> 165 | N6: =SUMIFS(Transactions!$E:$E,Transactions!$C:$C,$B6,Transactions!$B:$B,"Expense",Transactions!$I:$I,4) -> 0 | O6: =N6-M6 -> -165 | P6: =$C6 -> 165 | Q6: =SUMIFS(Transactions!$E:$E,Transactions!$C:$C,$B6,Transactions!$B:$B,"Expense",Transactions!$I:$I,5) -> 0 | R6: =Q6-P6 -> -165 | S6: =$C6 -> 165 | T6: =SUMIFS(Transactions!$E:$E,Transactions!$C:$C,$B6,Transactions!$B:$B,"Expense",Transactions!$I:$I,6) -> 0 | U6: =T6-S6 -> -165 | V6: =$C6 -> 165 | W6: =SUMIFS(Transactions!$E:$E,Transactions!$C:$C,$B6,Transactions!$B:$B,"Expense",Transactions!$I:$I,7) -> 0 | X6: =W6-V6 -> -165 | Y6: =$C6 -> 165 | Z6: =SUMIFS(Transactions!$E:$E,Transactions!$C:$C,$B6,Transactions!$B:$B,"Expense",Transactions!$I:$I,8) -> 0 | AA6: =Z6-Y6 -> -165 | AB6: =$C6 -> 165 | AC6: =SUMIFS(Transactions!$E:$E,Transactions!$C:$C,$B6,Transactions!$B:$B,"Expense",Transactions!$I:$I,9) -> 0 | AD6: =AC6-AB6 -> -165 | AE6: =$C6 -> 165 | AF6: =SUMIFS(Transactions!$E:$E,Transactions!$C:$C,$B6,Transactions!$B:$B,"Expense",Transactions!$I:$I,10) -> 0 | AG6: =AF6-AE6 -> -165 | AH6: =$C6 -> 165 | AI6: =SUMIFS(Transactions!$E:$E,Transactions!$C:$C,$B6,Transactions!$B:$B,"Expense",Transactions!$I:$I,11) -> 0 | AJ6: =AI6-AH6 -> -165 | AK6: =$C6 -> 165 | AL6: =SUMIFS(Transactions!$E:$E,Transactions!$C:$C,$B6,Transactions!$B:$B,"Expense",Transactions!$I:$I,12) -> 0 | AM6: =AL6-AK6 -> -165
A7: GIVING | B7: Charity - Perez Uni | C7: 50 | D7: =$C7 -> 50 | E7: =SUMIFS(Transactions!$E:$E,Transactions!$C:$C,$B7,Transactions!$B:$B,"Expense",Transactions!$I:$I,1) -> 50 | F7: =E7-D7 -> 0 | G7: =$C7 -> 50 | H7: =SUMIFS(Transactions!$E:$E,Transactions!$C:$C,$B7,Transactions!$B:$B,"Expense",Transactions!$I:$I,2) -> 0 | I7: =H7-G7 -> -50 | J7: =$C7 -> 50 | K7: =SUMIFS(Transactions!$E:$E,Transactions!$C:$C,$B7,Transactions!$B:$B,"Expense",Transactions!$I:$I,3) -> 0 | L7: =K7-J7 -> -50 | M7: =$C7 -> 50 | N7: =SUMIFS(Transactions!$E:$E,Transactions!$C:$C,$B7,Transactions!$B:$B,"Expense",Transactions!$I:$I,4) -> 0 | O7: =N7-M7 -> -50 | P7: =$C7 -> 50 | Q7: =SUMIFS(Transactions!$E:$E,Transactions!$C:$C,$B7,Transactions!$B:$B,"Expense",Transactions!$I:$I,5) -> 0 | R7: =Q7-P7 -> -50 | S7: =$C7 -> 50 | T7: =SUMIFS(Transactions!$E:$E,Transactions!$C:$C,$B7,Transactions!$B:$B,"Expense",Transactions!$I:$I,6) -> 0 | U7: =T7-S7 -> -50 | V7: =$C7 -> 50 | W7: =SUMIFS(Transactions!$E:$E,Transactions!$C:$C,$B7,Transactions!$B:$B,"Expense",Transactions!$I:$I,7) -> 0 | X7: =W7-V7 -> -50 | Y7: =$C7 -> 50 | Z7: =SUMIFS(Transactions!$E:$E,Transactions!$C:$C,$B7,Transactions!$B:$B,"Expense",Transactions!$I:$I,8) -> 0 | AA7: =Z7-Y7 -> -50 | AB7: =$C7 -> 50 | AC7: =SUMIFS(Transactions!$E:$E,Transactions!$C:$C,$B7,Transactions!$B:$B,"Expense",Transactions!$I:$I,9) -> 0 | AD7: =AC7-AB7 -> -50 | AE7: =$C7 -> 50 | AF7: =SUMIFS(Transactions!$E:$E,Transactions!$C:$C,$B7,Transactions!$B:$B,"Expense",Transactions!$I:$I,10) -> 0 | AG7: =AF7-AE7 -> -50 | AH7: =$C7 -> 50 | AI7: =SUMIFS(Transactions!$E:$E,Transactions!$C:$C,$B7,Transactions!$B:$B,"Expense",Transactions!$I:$I,11) -> 0 | AJ7: =AI7-AH7 -> -50 | AK7: =$C7 -> 50 | AL7: =SUMIFS(Transactions!$E:$E,Transactions!$C:$C,$B7,Transactions!$B:$B,"Expense",Transactions!$I:$I,12) -> 0 | AM7: =AL7-AK7 -> -50
A8: GIVING | B8: Charity - JPC Utilities | C8: 100 | D8: =$C8 -> 100 | E8: =SUMIFS(Transactions!$E:$E,Transactions!$C:$C,$B8,Transactions!$B:$B,"Expense",Transactions!$I:$I,1) -> 100 | F8: =E8-D8 -> 0 | G8: =$C8 -> 100 | H8: =SUMIFS(Transactions!$E:$E,Transactions!$C:$C,$B8,Transactions!$B:$B,"Expense",Transactions!$I:$I,2) -> 0 | I8: =H8-G8 -> -100 | J8: =$C8 -> 100 | K8: =SUMIFS(Transactions!$E:$E,Transactions!$C:$C,$B8,Transactions!$B:$B,"Expense",Transactions!$I:$I,3) -> 0 | L8: =K8-J8 -> -100 | M8: =$C8 -> 100 | N8: =SUMIFS(Transactions!$E:$E,Transactions!$C:$C,$B8,Transactions!$B:$B,"Expense",Transactions!$I:$I,4) -> 0 | O8: =N8-M8 -> -100 | P8: =$C8 -> 100 | Q8: =SUMIFS(Transactions!$E:$E,Transactions!$C:$C,$B8,Transactions!$B:$B,"Expense",Transactions!$I:$I,5) -> 0 | R8: =Q8-P8 -> -100 | S8: =$C8 -> 100 | T8: =SUMIFS(Transactions!$E:$E,Transactions!$C:$C,$B8,Transactions!$B:$B,"Expense",Transactions!$I:$I,6) -> 0 | U8: =T8-S8 -> -100 | V8: =$C8 -> 100 | W8: =SUMIFS(Transactions!$E:$E,Transactions!$C:$C,$B8,Transactions!$B:$B,"Expense",Transactions!$I:$I,7) -> 0 | X8: =W8-V8 -> -100 | Y8: =$C8 -> 100 | Z8: =SUMIFS(Transactions!$E:$E,Transactions!$C:$C,$B8,Transactions!$B:$B,"Expense",Transactions!$I:$I,8) -> 0 | AA8: =Z8-Y8 -> -100 | AB8: =$C8 -> 100 | AC8: =SUMIFS(Transactions!$E:$E,Transactions!$C:$C,$B8,Transactions!$B:$B,"Expense",Transactions!$I:$I,9) -> 0 | AD8: =AC8-AB8 -> -100 | AE8: =$C8 -> 100 | AF8: =SUMIFS(Transactions!$E:$E,Transactions!$C:$C,$B8,Transactions!$B:$B,"Expense",Transactions!$I:$I,10) -> 0 | AG8: =AF8-AE8 -> -100 | AH8: =$C8 -> 100 | AI8: =SUMIFS(Transactions!$E:$E,Transactions!$C:$C,$B8,Transactions!$B:$B,"Expense",Transactions!$I:$I,11) -> 0 | AJ8: =AI8-AH8 -> -100 | AK8: =$C8 -> 100 | AL8: =SUMIFS(Transactions!$E:$E,Transactions!$C:$C,$B8,Transactions!$B:$B,"Expense",Transactions!$I:$I,12) -> 0 | AM8: =AL8-AK8 -> -100
A9: GIVING | B9: Donations (Variable) | C9: 90 | D9: =$C9 -> 90 | E9: =SUMIFS(Transactions!$E:$E,Transactions!$C:$C,$B9,Transactions!$B:$B,"Expense",Transactions!$I:$I,1) -> 34 | F9: =E9-D9 -> -56 | G9: =$C9 -> 90 | H9: =SUMIFS(Transactions!$E:$E,Transactions!$C:$C,$B9,Transactions!$B:$B,"Expense",Transactions!$I:$I,2) -> 0 | I9: =H9-G9 -> -90 | J9: =$C9 -> 90 | K9: =SUMIFS(Transactions!$E:$E,Transactions!$C:$C,$B9,Transactions!$B:$B,"Expense",Transactions!$I:$I,3) -> 0 | L9: =K9-J9 -> -90 | M9: =$C9 -> 90 | N9: =SUMIFS(Transactions!$E:$E,Transactions!$C:$C,$B9,Transactions!$B:$B,"Expense",Transactions!$I:$I,4) -> 0 | O9: =N9-M9 -> -90 | P9: =$C9 -> 90 | Q9: =SUMIFS(Transactions!$E:$E,Transactions!$C:$C,$B9,Transactions!$B:$B,"Expense",Transactions!$I:$I,5) -> 0 | R9: =Q9-P9 -> -90 | S9: =$C9 -> 90 | T9: =SUMIFS(Transactions!$E:$E,Transactions!$C:$C,$B9,Transactions!$B:$B,"Expense",Transactions!$I:$I,6) -> 0 | U9: =T9-S9 -> -90 | V9: =$C9 -> 90 | W9: =SUMIFS(Transactions!$E:$E,Transactions!$C:$C,$B9,Transactions!$B:$B,"Expense",Transactions!$I:$I,7) -> 0 | X9: =W9-V9 -> -90 | Y9: =$C9 -> 90 | Z9: =SUMIFS(Transactions!$E:$E,Transactions!$C:$C,$B9,Transactions!$B:$B,"Expense",Transactions!$I:$I,8) -> 0 | AA9: =Z9-Y9 -> -90 | AB9: =$C9 -> 90 | AC9: =SUMIFS(Transactions!$E:$E,Transactions!$C:$C,$B9,Transactions!$B:$B,"Expense",Transactions!$I:$I,9) -> 0 | AD9: =AC9-AB9 -> -90 | AE9: =$C9 -> 90 | AF9: =SUMIFS(Transactions!$E:$E,Transactions!$C:$C,$B9,Transactions!$B:$B,"Expense",Transactions!$I:$I,10) -> 0 | AG9: =AF9-AE9 -> -90 | AH9: =$C9 -> 90 | AI9: =SUMIFS(Transactions!$E:$E,Transactions!$C:$C,$B9,Transactions!$B:$B,"Expense",Transactions!$I:$I,11) -> 0 | AJ9: =AI9-AH9 -> -90 | AK9: =$C9 -> 90 | AL9: =SUMIFS(Transactions!$E:$E,Transactions!$C:$C,$B9,Transactions!$B:$B,"Expense",Transactions!$I:$I,12) -> 0 | AM9: =AL9-AK9 -> -90
A10: FIXED | B10: Rent | C10: 550 | D10: =$C10 -> 550 | E10: =SUMIFS(Transactions!$E:$E,Transactions!$C:$C,$B10,Transactions!$B:$B,"Expense",Transactions!$I:$I,1) -> 0 | F10: =E10-D10 -> -550 | G10: =$C10 -> 550 | H10: =SUMIFS(Transactions!$E:$E,Transactions!$C:$C,$B10,Transactions!$B:$B,"Expense",Transactions!$I:$I,2) -> 0 | I10: =H10-G10 -> -550 | J10: =$C10 -> 550 | K10: =SUMIFS(Transactions!$E:$E,Transactions!$C:$C,$B10,Transactions!$B:$B,"Expense",Transactions!$I:$I,3) -> 0 | L10: =K10-J10 -> -550 | M10: =$C10 -> 550 | N10: =SUMIFS(Transactions!$E:$E,Transactions!$C:$C,$B10,Transactions!$B:$B,"Expense",Transactions!$I:$I,4) -> 0 | O10: =N10-M10 -> -550 | P10: =$C10 -> 550 | Q10: =SUMIFS(Transactions!$E:$E,Transactions!$C:$C,$B10,Transactions!$B:$B,"Expense",Transactions!$I:$I,5) -> 0 | R10: =Q10-P10 -> -550 | S10: =$C10 -> 550 | T10: =SUMIFS(Transactions!$E:$E,Transactions!$C:$C,$B10,Transactions!$B:$B,"Expense",Transactions!$I:$I,6) -> 0 | U10: =T10-S10 -> -550 | V10: =$C10 -> 550 | W10: =SUMIFS(Transactions!$E:$E,Transactions!$C:$C,$B10,Transactions!$B:$B,"Expense",Transactions!$I:$I,7) -> 0 | X10: =W10-V10 -> -550 | Y10: =$C10 -> 550 | Z10: =SUMIFS(Transactions!$E:$E,Transactions!$C:$C,$B10,Transactions!$B:$B,"Expense",Transactions!$I:$I,8) -> 0 | AA10: =Z10-Y10 -> -550 | AB10: =$C10 -> 550 | AC10: =SUMIFS(Transactions!$E:$E,Transactions!$C:$C,$B10,Transactions!$B:$B,"Expense",Transactions!$I:$I,9) -> 0 | AD10: =AC10-AB10 -> -550 | AE10: =$C10 -> 550 | AF10: =SUMIFS(Transactions!$E:$E,Transactions!$C:$C,$B10,Transactions!$B:$B,"Expense",Transactions!$I:$I,10) -> 0 | AG10: =AF10-AE10 -> -550 | AH10: =$C10 -> 550 | AI10: =SUMIFS(Transactions!$E:$E,Transactions!$C:$C,$B10,Transactions!$B:$B,"Expense",Transactions!$I:$I,11) -> 0 | AJ10: =AI10-AH10 -> -550 | AK10: =$C10 -> 550 | AL10: =SUMIFS(Transactions!$E:$E,Transactions!$C:$C,$B10,Transactions!$B:$B,"Expense",Transactions!$I:$I,12) -> 0 | AM10: =AL10-AK10 -> -550
A11: FIXED | B11: Insurance | C11: 175 | D11: =$C11 -> 175 | E11: =SUMIFS(Transactions!$E:$E,Transactions!$C:$C,$B11,Transactions!$B:$B,"Expense",Transactions!$I:$I,1) -> 0 | F11: =E11-D11 -> -175 | G11: =$C11 -> 175 | H11: =SUMIFS(Transactions!$E:$E,Transactions!$C:$C,$B11,Transactions!$B:$B,"Expense",Transactions!$I:$I,2) -> 0 | I11: =H11-G11 -> -175 | J11: =$C11 -> 175 | K11: =SUMIFS(Transactions!$E:$E,Transactions!$C:$C,$B11,Transactions!$B:$B,"Expense",Transactions!$I:$I,3) -> 0 | L11: =K11-J11 -> -175 | M11: =$C11 -> 175 | N11: =SUMIFS(Transactions!$E:$E,Transactions!$C:$C,$B11,Transactions!$B:$B,"Expense",Transactions!$I:$I,4) -> 0 | O11: =N11-M11 -> -175 | P11: =$C11 -> 175 | Q11: =SUMIFS(Transactions!$E:$E,Transactions!$C:$C,$B11,Transactions!$B:$B,"Expense",Transactions!$I:$I,5) -> 0 | R11: =Q11-P11 -> -175 | S11: =$C11 -> 175 | T11: =SUMIFS(Transactions!$E:$E,Transactions!$C:$C,$B11,Transactions!$B:$B,"Expense",Transactions!$I:$I,6) -> 0 | U11: =T11-S11 -> -175 | V11: =$C11 -> 175 | W11: =SUMIFS(Transactions!$E:$E,Transactions!$C:$C,$B11,Transactions!$B:$B,"Expense",Transactions!$I:$I,7) -> 0 | X11: =W11-V11 -> -175 | Y11: =$C11 -> 175 | Z11: =SUMIFS(Transactions!$E:$E,Transactions!$C:$C,$B11,Transactions!$B:$B,"Expense",Transactions!$I:$I,8) -> 0 | AA11: =Z11-Y11 -> -175 | AB11: =$C11 -> 175 | AC11: =SUMIFS(Transactions!$E:$E,Transactions!$C:$C,$B11,Transactions!$B:$B,"Expense",Transactions!$I:$I,9) -> 0 | AD11: =AC11-AB11 -> -175 | AE11: =$C11 -> 175 | AF11: =SUMIFS(Transactions!$E:$E,Transactions!$C:$C,$B11,Transactions!$B:$B,"Expense",Transactions!$I:$I,10) -> 0 | AG11: =AF11-AE11 -> -175 | AH11: =$C11 -> 175 | AI11: =SUMIFS(Transactions!$E:$E,Transactions!$C:$C,$B11,Transactions!$B:$B,"Expense",Transactions!$I:$I,11) -> 0 | AJ11: =AI11-AH11 -> -175 | AK11: =$C11 -> 175 | AL11: =SUMIFS(Transactions!$E:$E,Transactions!$C:$C,$B11,Transactions!$B:$B,"Expense",Transactions!$I:$I,12) -> 0 | AM11: =AL11-AK11 -> -175
A12: FIXED | B12: Road Tax | C12: 34 | D12: =$C12 -> 34 | E12: =SUMIFS(Transactions!$E:$E,Transactions!$C:$C,$B12,Transactions!$B:$B,"Expense",Transactions!$I:$I,1) -> 0 | F12: =E12-D12 -> -34 | G12: =$C12 -> 34 | H12: =SUMIFS(Transactions!$E:$E,Transactions!$C:$C,$B12,Transactions!$B:$B,"Expense",Transactions!$I:$I,2) -> 0 | I12: =H12-G12 -> -34 | J12: =$C12 -> 34 | K12: =SUMIFS(Transactions!$E:$E,Transactions!$C:$C,$B12,Transactions!$B:$B,"Expense",Transactions!$I:$I,3) -> 0 | L12: =K12-J12 -> -34 | M12: =$C12 -> 34 | N12: =SUMIFS(Transactions!$E:$E,Transactions!$C:$C,$B12,Transactions!$B:$B,"Expense",Transactions!$I:$I,4) -> 0 | O12: =N12-M12 -> -34 | P12: =$C12 -> 34 | Q12: =SUMIFS(Transactions!$E:$E,Transactions!$C:$C,$B12,Transactions!$B:$B,"Expense",Transactions!$I:$I,5) -> 0 | R12: =Q12-P12 -> -34 | S12: =$C12 -> 34 | T12: =SUMIFS(Transactions!$E:$E,Transactions!$C:$C,$B12,Transactions!$B:$B,"Expense",Transactions!$I:$I,6) -> 0 | U12: =T12-S12 -> -34 | V12: =$C12 -> 34 | W12: =SUMIFS(Transactions!$E:$E,Transactions!$C:$C,$B12,Transactions!$B:$B,"Expense",Transactions!$I:$I,7) -> 0 | X12: =W12-V12 -> -34 | Y12: =$C12 -> 34 | Z12: =SUMIFS(Transactions!$E:$E,Transactions!$C:$C,$B12,Transactions!$B:$B,"Expense",Transactions!$I:$I,8) -> 0 | AA12: =Z12-Y12 -> -34 | AB12: =$C12 -> 34 | AC12: =SUMIFS(Transactions!$E:$E,Transactions!$C:$C,$B12,Transactions!$B:$B,"Expense",Transactions!$I:$I,9) -> 0 | AD12: =AC12-AB12 -> -34 | AE12: =$C12 -> 34 | AF12: =SUMIFS(Transactions!$E:$E,Transactions!$C:$C,$B12,Transactions!$B:$B,"Expense",Transactions!$I:$I,10) -> 0 | AG12: =AF12-AE12 -> -34 | AH12: =$C12 -> 34 | AI12: =SUMIFS(Transactions!$E:$E,Transactions!$C:$C,$B12,Transactions!$B:$B,"Expense",Transactions!$I:$I,11) -> 0 | AJ12: =AI12-AH12 -> -34 | AK12: =$C12 -> 34 | AL12: =SUMIFS(Transactions!$E:$E,Transactions!$C:$C,$B12,Transactions!$B:$B,"Expense",Transactions!$I:$I,12) -> 0 | AM12: =AL12-AK12 -> -34
A13: FIXED | B13: Water Bill | C13: 93 | D13: =$C13 -> 93 | E13: =SUMIFS(Transactions!$E:$E,Transactions!$C:$C,$B13,Transactions!$B:$B,"Expense",Transactions!$I:$I,1) -> 92.77 | F13: =E13-D13 -> -0.23 | G13: =$C13 -> 93 | H13: =SUMIFS(Transactions!$E:$E,Transactions!$C:$C,$B13,Transactions!$B:$B,"Expense",Transactions!$I:$I,2) -> 0 | I13: =H13-G13 -> -93 | J13: =$C13 -> 93 | K13: =SUMIFS(Transactions!$E:$E,Transactions!$C:$C,$B13,Transactions!$B:$B,"Expense",Transactions!$I:$I,3) -> 0 | L13: =K13-J13 -> -93 | M13: =$C13 -> 93 | N13: =SUMIFS(Transactions!$E:$E,Transactions!$C:$C,$B13,Transactions!$B:$B,"Expense",Transactions!$I:$I,4) -> 0 | O13: =N13-M13 -> -93 | P13: =$C13 -> 93 | Q13: =SUMIFS(Transactions!$E:$E,Transactions!$C:$C,$B13,Transactions!$B:$B,"Expense",Transactions!$I:$I,5) -> 0 | R13: =Q13-P13 -> -93 | S13: =$C13 -> 93 | T13: =SUMIFS(Transactions!$E:$E,Transactions!$C:$C,$B13,Transactions!$B:$B,"Expense",Transactions!$I:$I,6) -> 0 | U13: =T13-S13 -> -93 | V13: =$C13 -> 93 | W13: =SUMIFS(Transactions!$E:$E,Transactions!$C:$C,$B13,Transactions!$B:$B,"Expense",Transactions!$I:$I,7) -> 0 | X13: =W13-V13 -> -93 | Y13: =$C13 -> 93 | Z13: =SUMIFS(Transactions!$E:$E,Transactions!$C:$C,$B13,Transactions!$B:$B,"Expense",Transactions!$I:$I,8) -> 0 | AA13: =Z13-Y13 -> -93 | AB13: =$C13 -> 93 | AC13: =SUMIFS(Transactions!$E:$E,Transactions!$C:$C,$B13,Transactions!$B:$B,"Expense",Transactions!$I:$I,9) -> 0 | AD13: =AC13-AB13 -> -93 | AE13: =$C13 -> 93 | AF13: =SUMIFS(Transactions!$E:$E,Transactions!$C:$C,$B13,Transactions!$B:$B,"Expense",Transactions!$I:$I,10) -> 0 | AG13: =AF13-AE13 -> -93 | AH13: =$C13 -> 93 | AI13: =SUMIFS(Transactions!$E:$E,Transactions!$C:$C,$B13,Transactions!$B:$B,"Expense",Transactions!$I:$I,11) -> 0 | AJ13: =AI13-AH13 -> -93 | AK13: =$C13 -> 93 | AL13: =SUMIFS(Transactions!$E:$E,Transactions!$C:$C,$B13,Transactions!$B:$B,"Expense",Transactions!$I:$I,12) -> 0 | AM13: =AL13-AK13 -> -93
A14: FIXED | B14: Electricity & Gas | C14: 200 | D14: =$C14 -> 200 | E14: =SUMIFS(Transactions!$E:$E,Transactions!$C:$C,$B14,Transactions!$B:$B,"Expense",Transactions!$I:$I,1) -> 50 | F14: =E14-D14 -> -150 | G14: =$C14 -> 200 | H14: =SUMIFS(Transactions!$E:$E,Transactions!$C:$C,$B14,Transactions!$B:$B,"Expense",Transactions!$I:$I,2) -> 0 | I14: =H14-G14 -> -200 | J14: =$C14 -> 200 | K14: =SUMIFS(Transactions!$E:$E,Transactions!$C:$C,$B14,Transactions!$B:$B,"Expense",Transactions!$I:$I,3) -> 0 | L14: =K14-J14 -> -200 | M14: =$C14 -> 200 | N14: =SUMIFS(Transactions!$E:$E,Transactions!$C:$C,$B14,Transactions!$B:$B,"Expense",Transactions!$I:$I,4) -> 0 | O14: =N14-M14 -> -200 | P14: =$C14 -> 200 | Q14: =SUMIFS(Transactions!$E:$E,Transactions!$C:$C,$B14,Transactions!$B:$B,"Expense",Transactions!$I:$I,5) -> 0 | R14: =Q14-P14 -> -200 | S14: =$C14 -> 200 | T14: =SUMIFS(Transactions!$E:$E,Transactions!$C:$C,$B14,Transactions!$B:$B,"Expense",Transactions!$I:$I,6) -> 0 | U14: =T14-S14 -> -200 | V14: =$C14 -> 200 | W14: =SUMIFS(Transactions!$E:$E,Transactions!$C:$C,$B14,Transactions!$B:$B,"Expense",Transactions!$I:$I,7) -> 0 | X14: =W14-V14 -> -200 | Y14: =$C14 -> 200 | Z14: =SUMIFS(Transactions!$E:$E,Transactions!$C:$C,$B14,Transactions!$B:$B,"Expense",Transactions!$I:$I,8) -> 0 | AA14: =Z14-Y14 -> -200 | AB14: =$C14 -> 200 | AC14: =SUMIFS(Transactions!$E:$E,Transactions!$C:$C,$B14,Transactions!$B:$B,"Expense",Transactions!$I:$I,9) -> 0 | AD14: =AC14-AB14 -> -200 | AE14: =$C14 -> 200 | AF14: =SUMIFS(Transactions!$E:$E,Transactions!$C:$C,$B14,Transactions!$B:$B,"Expense",Transactions!$I:$I,10) -> 0 | AG14: =AF14-AE14 -> -200 | AH14: =$C14 -> 200 | AI14: =SUMIFS(Transactions!$E:$E,Transactions!$C:$C,$B14,Transactions!$B:$B,"Expense",Transactions!$I:$I,11) -> 0 | AJ14: =AI14-AH14 -> -200 | AK14: =$C14 -> 200 | AL14: =SUMIFS(Transactions!$E:$E,Transactions!$C:$C,$B14,Transactions!$B:$B,"Expense",Transactions!$I:$I,12) -> 0 | AM14: =AL14-AK14 -> -200
A15: FIXED | B15: Community Fibre / Internet | C15: 37 | D15: =$C15 -> 37 | E15: =SUMIFS(Transactions!$E:$E,Transactions!$C:$C,$B15,Transactions!$B:$B,"Expense",Transactions!$I:$I,1) -> 36.83 | F15: =E15-D15 -> -0.17 | G15: =$C15 -> 37 | H15: =SUMIFS(Transactions!$E:$E,Transactions!$C:$C,$B15,Transactions!$B:$B,"Expense",Transactions!$I:$I,2) -> 0 | I15: =H15-G15 -> -37 | J15: =$C15 -> 37 | K15: =SUMIFS(Transactions!$E:$E,Transactions!$C:$C,$B15,Transactions!$B:$B,"Expense",Transactions!$I:$I,3) -> 0 | L15: =K15-J15 -> -37 | M15: =$C15 -> 37 | N15: =SUMIFS(Transactions!$E:$E,Transactions!$C:$C,$B15,Transactions!$B:$B,"Expense",Transactions!$I:$I,4) -> 0 | O15: =N15-M15 -> -37 | P15: =$C15 -> 37 | Q15: =SUMIFS(Transactions!$E:$E,Transactions!$C:$C,$B15,Transactions!$B:$B,"Expense",Transactions!$I:$I,5) -> 0 | R15: =Q15-P15 -> -37 | S15: =$C15 -> 37 | T15: =SUMIFS(Transactions!$E:$E,Transactions!$C:$C,$B15,Transactions!$B:$B,"Expense",Transactions!$I:$I,6) -> 0 | U15: =T15-S15 -> -37 | V15: =$C15 -> 37 | W15: =SUMIFS(Transactions!$E:$E,Transactions!$C:$C,$B15,Transactions!$B:$B,"Expense",Transactions!$I:$I,7) -> 0 | X15: =W15-V15 -> -37 | Y15: =$C15 -> 37 | Z15: =SUMIFS(Transactions!$E:$E,Transactions!$C:$C,$B15,Transactions!$B:$B,"Expense",Transactions!$I:$I,8) -> 0 | AA15: =Z15-Y15 -> -37 | AB15: =$C15 -> 37 | AC15: =SUMIFS(Transactions!$E:$E,Transactions!$C:$C,$B15,Transactions!$B:$B,"Expense",Transactions!$I:$I,9) -> 0 | AD15: =AC15-AB15 -> -37 | AE15: =$C15 -> 37 | AF15: =SUMIFS(Transactions!$E:$E,Transactions!$C:$C,$B15,Transactions!$B:$B,"Expense",Transactions!$I:$I,10) -> 0 | AG15: =AF15-AE15 -> -37 | AH15: =$C15 -> 37 | AI15: =SUMIFS(Transactions!$E:$E,Transactions!$C:$C,$B15,Transactions!$B:$B,"Expense",Transactions!$I:$I,11) -> 0 | AJ15: =AI15-AH15 -> -37 | AK15: =$C15 -> 37 | AL15: =SUMIFS(Transactions!$E:$E,Transactions!$C:$C,$B15,Transactions!$B:$B,"Expense",Transactions!$I:$I,12) -> 0 | AM15: =AL15-AK15 -> -37
A16: FIXED | B16: iPhone Payments | C16: 108 | D16: =$C16 -> 108 | E16: =SUMIFS(Transactions!$E:$E,Transactions!$C:$C,$B16,Transactions!$B:$B,"Expense",Transactions!$I:$I,1) -> 53.95 | F16: =E16-D16 -> -54.05 | G16: =$C16 -> 108 | H16: =SUMIFS(Transactions!$E:$E,Transactions!$C:$C,$B16,Transactions!$B:$B,"Expense",Transactions!$I:$I,2) -> 0 | I16: =H16-G16 -> -108 | J16: =$C16 -> 108 | K16: =SUMIFS(Transactions!$E:$E,Transactions!$C:$C,$B16,Transactions!$B:$B,"Expense",Transactions!$I:$I,3) -> 0 | L16: =K16-J16 -> -108 | M16: =$C16 -> 108 | N16: =SUMIFS(Transactions!$E:$E,Transactions!$C:$C,$B16,Transactions!$B:$B,"Expense",Transactions!$I:$I,4) -> 0 | O16: =N16-M16 -> -108 | P16: =$C16 -> 108 | Q16: =SUMIFS(Transactions!$E:$E,Transactions!$C:$C,$B16,Transactions!$B:$B,"Expense",Transactions!$I:$I,5) -> 0 | R16: =Q16-P16 -> -108 | S16: =$C16 -> 108 | T16: =SUMIFS(Transactions!$E:$E,Transactions!$C:$C,$B16,Transactions!$B:$B,"Expense",Transactions!$I:$I,6) -> 0 | U16: =T16-S16 -> -108 | V16: =$C16 -> 108 | W16: =SUMIFS(Transactions!$E:$E,Transactions!$C:$C,$B16,Transactions!$B:$B,"Expense",Transactions!$I:$I,7) -> 0 | X16: =W16-V16 -> -108 | Y16: =$C16 -> 108 | Z16: =SUMIFS(Transactions!$E:$E,Transactions!$C:$C,$B16,Transactions!$B:$B,"Expense",Transactions!$I:$I,8) -> 0 | AA16: =Z16-Y16 -> -108 | AB16: =$C16 -> 108 | AC16: =SUMIFS(Transactions!$E:$E,Transactions!$C:$C,$B16,Transactions!$B:$B,"Expense",Transactions!$I:$I,9) -> 0 | AD16: =AC16-AB16 -> -108 | AE16: =$C16 -> 108 | AF16: =SUMIFS(Transactions!$E:$E,Transactions!$C:$C,$B16,Transactions!$B:$B,"Expense",Transactions!$I:$I,10) -> 0 | AG16: =AF16-AE16 -> -108 | AH16: =$C16 -> 108 | AI16: =SUMIFS(Transactions!$E:$E,Transactions!$C:$C,$B16,Transactions!$B:$B,"Expense",Transactions!$I:$I,11) -> 0 | AJ16: =AI16-AH16 -> -108 | AK16: =$C16 -> 108 | AL16: =SUMIFS(Transactions!$E:$E,Transactions!$C:$C,$B16,Transactions!$B:$B,"Expense",Transactions!$I:$I,12) -> 0 | AM16: =AL16-AK16 -> -108
... A21: FIXED | B21: Laptop | C21: 43 | D21: =$C21 -> 43 | E21: =SUMIFS(Transactions!$E:$E,Transactions!$C:$C,$B21,Transactions!$B:$B,"Expense",Transactions!$I:$I,1) -> 43 | F21: =E21-D21 -> 0 | G21: =$C21 -> 43 | H21: =SUMIFS(Transactions!$E:$E,Transactions!$C:$C,$B21,Transactions!$B:$B,"Expense",Transactions!$I:$I,2) -> 0 | I21: =H21-G21 -> -43 | J21: =$C21 -> 43 | K21: =SUMIFS(Transactions!$E:$E,Transactions!$C:$C,$B21,Transactions!$B:$B,"Expense",Transactions!$I:$I,3) -> 0 | L21: =K21-J21 -> -43 | M21: =$C21 -> 43 | N21: =SUMIFS(Transactions!$E:$E,Transactions!$C:$C,$B21,Transactions!$B:$B,"Expense",Transactions!$I:$I,4) -> 0 | O21: =N21-M21 -> -43 | P21: =$C21 -> 43 | Q21: =SUMIFS(Transactions!$E:$E,Transactions!$C:$C,$B21,Transactions!$B:$B,"Expense",Transactions!$I:$I,5) -> 0 | R21: =Q21-P21 -> -43 | S21: =$C21 -> 43 | T21: =SUMIFS(Transactions!$E:$E,Transactions!$C:$C,$B21,Transactions!$B:$B,"Expense",Transactions!$I:$I,6) -> 0 | U21: =T21-S21 -> -43 | V21: =$C21 -> 43 | W21: =SUMIFS(Transactions!$E:$E,Transactions!$C:$C,$B21,Transactions!$B:$B,"Expense",Transactions!$I:$I,7) -> 0 | X21: =W21-V21 -> -43 | Y21: =$C21 -> 43 | Z21: =SUMIFS(Transactions!$E:$E,Transactions!$C:$C,$B21,Transactions!$B:$B,"Expense",Transactions!$I:$I,8) -> 0 | AA21: =Z21-Y21 -> -43 | AB21: =$C21 -> 43 | AC21: =SUMIFS(Transactions!$E:$E,Transactions!$C:$C,$B21,Transactions!$B:$B,"Expense",Transactions!$I:$I,9) -> 0 | AD21: =AC21-AB21 -> -43 | AE21: =$C21 -> 43 | AF21: =SUMIFS(Transactions!$E:$E,Transactions!$C:$C,$B21,Transactions!$B:$B,"Expense",Transactions!$I:$I,10) -> 0 | AG21: =AF21-AE21 -> -43 | AH21: =$C21 -> 43 | AI21: =SUMIFS(Transactions!$E:$E,Transactions!$C:$C,$B21,Transactions!$B:$B,"Expense",Transactions!$I:$I,11) -> 0 | AJ21: =AI21-AH21 -> -43 | AK21: =$C21 -> 43 | AL21: =SUMIFS(Transactions!$E:$E,Transactions!$C:$C,$B21,Transactions!$B:$B,"Expense",Transactions!$I:$I,12) -> 0 | AM21: =AL21-AK21 -> -43
A22: FIXED | B22: One-Off Giving (Christmas) | C22: 500 | D22: =$C22 -> 500 | E22: =SUMIFS(Transactions!$E:$E,Transactions!$C:$C,$B22,Transactions!$B:$B,"Expense",Transactions!$I:$I,1) -> 457.37 | F22: =E22-D22 -> -42.63
A23: VARIABLE | B23: Food | C23: 150 | D23: =$C23 -> 150 | E23: =SUMIFS(Transactions!$E:$E,Transactions!$C:$C,$B23,Transactions!$B:$B,"Expense",Transactions!$I:$I,1) -> 0 | F23: =E23-D23 -> -150 | G23: =$C23 -> 150 | H23: =SUMIFS(Transactions!$E:$E,Transactions!$C:$C,$B23,Transactions!$B:$B,"Expense",Transactions!$I:$I,2) -> 0 | I23: =H23-G23 -> -150 | J23: =$C23 -> 150 | K23: =SUMIFS(Transactions!$E:$E,Transactions!$C:$C,$B23,Transactions!$B:$B,"Expense",Transactions!$I:$I,3) -> 0 | L23: =K23-J23 -> -150 | M23: =$C23 -> 150 | N23: =SUMIFS(Transactions!$E:$E,Transactions!$C:$C,$B23,Transactions!$B:$B,"Expense",Transactions!$I:$I,4) -> 0 | O23: =N23-M23 -> -150 | P23: =$C23 -> 150 | Q23: =SUMIFS(Transactions!$E:$E,Transactions!$C:$C,$B23,Transactions!$B:$B,"Expense",Transactions!$I:$I,5) -> 0 | R23: =Q23-P23 -> -150 | S23: =$C23 -> 150 | T23: =SUMIFS(Transactions!$E:$E,Transactions!$C:$C,$B23,Transactions!$B:$B,"Expense",Transactions!$I:$I,6) -> 0 | U23: =T23-S23 -> -150 | V23: =$C23 -> 150 | W23: =SUMIFS(Transactions!$E:$E,Transactions!$C:$C,$B23,Transactions!$B:$B,"Expense",Transactions!$I:$I,7) -> 0 | X23: =W23-V23 -> -150 | Y23: =$C23 -> 150 | Z23: =SUMIFS(Transactions!$E:$E,Transactions!$C:$C,$B23,Transactions!$B:$B,"Expense",Transactions!$I:$I,8) -> 0 | AA23: =Z23-Y23 -> -150 | AB23: =$C23 -> 150 | AC23: =SUMIFS(Transactions!$E:$E,Transactions!$C:$C,$B23,Transactions!$B:$B,"Expense",Transactions!$I:$I,9) -> 0 | AD23: =AC23-AB23 -> -150 | AE23: =$C23 -> 150 | AF23: =SUMIFS(Transactions!$E:$E,Transactions!$C:$C,$B23,Transactions!$B:$B,"Expense",Transactions!$I:$I,10) -> 0 | AG23: =AF23-AE23 -> -150 | AH23: =$C23 -> 150 | AI23: =SUMIFS(Transactions!$E:$E,Transactions!$C:$C,$B23,Transactions!$B:$B,"Expense",Transactions!$I:$I,11) -> 0 | AJ23: =AI23-AH23 -> -150 | AK23: =$C23 -> 150 | AL23: =SUMIFS(Transactions!$E:$E,Transactions!$C:$C,$B23,Transactions!$B:$B,"Expense",Transactions!$I:$I,12) -> 0 | AM23: =AL23-AK23 -> -150
